Workbook

Sheet Management Summary
A1: Northstar Industrial — Management Summary
A2: YTD June 2026 | FY2026 Forecast
A4: YTD Performance
A5: Revenue | B5: ='P&L'!N4 -> 5924302.2
A6: Revenue vs Budget | B6: ='P&L'!N22 -> 289978.13
A7: Operating Profit | B7: ='P&L'!N9 -> 1537340
A8: Operating Margin | B8: =IFERROR(B7/B5,0) -> 0.25949723
A11: FY2026 Outlook
A12: Revenue Forecast | B12: ='Forecast Assumptions'!B14 -> 12257891
A13: Revenue vs Budget | B13: ='Forecast Assumptions'!B16 -> 474451.59
A14: Operating Profit Forecast | B14: ='Forecast Assumptions'!B15 -> 3324153.1
A15: Operating Profit vs Budget | B15: ='Forecast Assumptions'!B17 -> 204574.98
A18: Management Commentary
A19: YTD revenue is €5.92m, €290k above budget (+5.1%)
A20: YTD operating profit is €1.54m, €52k above budget, with a 25.9% operating margin.
A21: Industrial Components has the highest YTD operating margin at 26.8%, while Automation Solutions generates the highest absolute operating profit at €625k.
A22: FY2026 revenue is forecast at €12.26m and operating profit at €3.32m, exceeding full-year budget by €474k and €205k respectively.
A23: The outlook assumes revenue 3% above budget in Jul–Dec, while COGS is 2% above budget, personnel remains on budget and Other OPEX is 2% below budget.

Sheet P&L
A1: Northstar Industrial – Management P&L 2026
A3: P&L Category | B3: 46023 | C3: =EDATE(B3,1) -> 46054 | D3: =EDATE(C3,1) -> 46082 | E3: =EDATE(D3,1) -> 46113 | F3: =EDATE(E3,1) -> 46143 | G3: =EDATE(F3,1) -> 46174 | H3: =EDATE(G3,1) -> 46204 | I3: =EDATE(H3,1) -> 46235 | J3: =EDATE(I3,1) -> 46266 | ... M3: =EDATE(L3,1) -> 46357 | N3: YTD Jun
A4: Revenue | B4: =SUMIFS(Actuals!$E:$E,Actuals!$G:$G,$A4,Actuals!$A:$A,">="&B$3,Actuals!$A:$A,"<"&EDATE(B$3,1)) -> 932646 | C4: =SUMIFS(tblActuals[Amount],tblActuals[P&L Category],$A4,tblActuals[Date],">="&C$3,tblActuals[Date],"<"&EDATE(C$3,1)) -> 926168.61 | D4: =SUMIFS(tblActuals[Amount],tblActuals[P&L Category],$A4,tblActuals[Date],">="&D$3,tblActuals[Date],"<"&EDATE(D$3,1)) -> 994175.52 | E4: =SUMIFS(tblActuals[Amount],tblActuals[P&L Category],$A4,tblActuals[Date],">="&E$3,tblActuals[Date],"<"&EDATE(E$3,1)) -> 988604.76 | F4: =SUMIFS(tblActuals[Amount],tblActuals[P&L Category],$A4,tblActuals[Date],">="&F$3,tblActuals[Date],"<"&EDATE(F$3,1)) -> 1050294.3 | G4: =SUMIFS(tblActuals[Amount],tblActuals[P&L Category],$A4,tblActuals[Date],">="&G$3,tblActuals[Date],"<"&EDATE(G$3,1)) -> 1032413 | H4: =SUMIFS(tblActuals[Amount],tblActuals[P&L Category],$A4,tblActuals[Date],">="&H$3,tblActuals[Date],"<"&EDATE(H$3,1)) -> 0 | I4: =SUMIFS(tblActuals[Amount],tblActuals[P&L Category],$A4,tblActuals[Date],">="&I$3,tblActuals[Date],"<"&EDATE(I$3,1)) -> 0 | J4: =SUMIFS(tblActuals[Amount],tblActuals[P&L Category],$A4,tblActuals[Date],">="&J$3,tblActuals[Date],"<"&EDATE(J$3,1)) -> 0 | ... M4: =SUMIFS(tblActuals[Amount],tblActuals[P&L Category],$A4,tblActuals[Date],">="&M$3,tblActuals[Date],"<"&EDATE(M$3,1)) -> 0 | N4: =SUM(B4:M4) -> 5924302.2
A5: COGS | B5: =SUMIFS(tblActuals[Amount],tblActuals[P&L Category],$A5,tblActuals[Date],">="&B$3,tblActuals[Date],"<"&EDATE(B$3,1)) -> -369111 | C5: =SUMIFS(tblActuals[Amount],tblActuals[P&L Category],$A5,tblActuals[Date],">="&C$3,tblActuals[Date],"<"&EDATE(C$3,1)) -> -365138.65 | D5: =SUMIFS(tblActuals[Amount],tblActuals[P&L Category],$A5,tblActuals[Date],">="&D$3,tblActuals[Date],"<"&EDATE(D$3,1)) -> -384165.6 | E5: =SUMIFS(tblActuals[Amount],tblActuals[P&L Category],$A5,tblActuals[Date],">="&E$3,tblActuals[Date],"<"&EDATE(E$3,1)) -> -391257.66 | F5: =SUMIFS(tblActuals[Amount],tblActuals[P&L Category],$A5,tblActuals[Date],">="&F$3,tblActuals[Date],"<"&EDATE(F$3,1)) -> -414074.76 | G5: =SUMIFS(tblActuals[Amount],tblActuals[P&L Category],$A5,tblActuals[Date],">="&G$3,tblActuals[Date],"<"&EDATE(G$3,1)) -> -398941.21 | H5: =SUMIFS(tblActuals[Amount],tblActuals[P&L Category],$A5,tblActuals[Date],">="&H$3,tblActuals[Date],"<"&EDATE(H$3,1)) -> 0 | I5: =SUMIFS(tblActuals[Amount],tblActuals[P&L Category],$A5,tblActuals[Date],">="&I$3,tblActuals[Date],"<"&EDATE(I$3,1)) -> 0 | ... M5: =SUMIFS(tblActuals[Amount],tblActuals[P&L Category],$A5,tblActuals[Date],">="&M$3,tblActuals[Date],"<"&EDATE(M$3,1)) -> 0 | N5: =SUM(B5:M5) -> -2322688.9
A6: Gross Profit | B6: =B4+B5 -> 563535 | C6: =C4+C5 -> 561029.96 | D6: =D4+D5 -> 610009.92 | E6: =E4+E5 -> 597347.1 | F6: =F4+F5 -> 636219.54 | G6: =G4+G5 -> 633471.83 | H6: =H4+H5 -> 0 | I6: =I4+I5 -> 0 | ... M6: =M4+M5 -> 0 | N6: =SUM(B6:M6) -> 3601613.4
A7: Personnel | B7: =SUMIFS(tblActuals[Amount],tblActuals[P&L Category],$A7,tblActuals[Date],">="&B$3,tblActuals[Date],"<"&EDATE(B$3,1)) -> -212006.4 | C7: =SUMIFS(tblActuals[Amount],tblActuals[P&L Category],$A7,tblActuals[Date],">="&C$3,tblActuals[Date],"<"&EDATE(C$3,1)) -> -204361.15 | D7: =SUMIFS(tblActuals[Amount],tblActuals[P&L Category],$A7,tblActuals[Date],">="&D$3,tblActuals[Date],"<"&EDATE(D$3,1)) -> -220172.16 | E7: =SUMIFS(tblActuals[Amount],tblActuals[P&L Category],$A7,tblActuals[Date],">="&E$3,tblActuals[Date],"<"&EDATE(E$3,1)) -> -224726.78 | F7: =SUMIFS(tblActuals[Amount],tblActuals[P&L Category],$A7,tblActuals[Date],">="&F$3,tblActuals[Date],"<"&EDATE(F$3,1)) -> -231749.76 | G7: =SUMIFS(tblActuals[Amount],tblActuals[P&L Category],$A7,tblActuals[Date],">="&G$3,tblActuals[Date],"<"&EDATE(G$3,1)) -> -228640.32 | H7: =SUMIFS(tblActuals[Amount],tblActuals[P&L Category],$A7,tblActuals[Date],">="&H$3,tblActuals[Date],"<"&EDATE(H$3,1)) -> 0 | I7: =SUMIFS(tblActuals[Amount],tblActuals[P&L Category],$A7,tblActuals[Date],">="&I$3,tblActuals[Date],"<"&EDATE(I$3,1)) -> 0 | ... M7: =SUMIFS(tblActuals[Amount],tblActuals[P&L Category],$A7,tblActuals[Date],">="&M$3,tblActuals[Date],"<"&EDATE(M$3,1)) -> 0 | N7: =SUM(B7:M7) -> -1321656.6
A8: Other OPEX | B8: =SUMIFS(tblActuals[Amount],tblActuals[P&L Category],$A8,tblActuals[Date],">="&B$3,tblActuals[Date],"<"&EDATE(B$3,1)) -> -119230.8 | C8: =SUMIFS(tblActuals[Amount],tblActuals[P&L Category],$A8,tblActuals[Date],">="&C$3,tblActuals[Date],"<"&EDATE(C$3,1)) -> -115615.46 | D8: =SUMIFS(tblActuals[Amount],tblActuals[P&L Category],$A8,tblActuals[Date],">="&D$3,tblActuals[Date],"<"&EDATE(D$3,1)) -> -122776.69 | E8: =SUMIFS(tblActuals[Amount],tblActuals[P&L Category],$A8,tblActuals[Date],">="&E$3,tblActuals[Date],"<"&EDATE(E$3,1)) -> -126384.66 | F8: =SUMIFS(tblActuals[Amount],tblActuals[P&L Category],$A8,tblActuals[Date],">="&F$3,tblActuals[Date],"<"&EDATE(F$3,1)) -> -131110.32 | G8: =SUMIFS(tblActuals[Amount],tblActuals[P&L Category],$A8,tblActuals[Date],">="&G$3,tblActuals[Date],"<"&EDATE(G$3,1)) -> -127498.86 | H8: =SUMIFS(tblActuals[Amount],tblActuals[P&L Category],$A8,tblActuals[Date],">="&H$3,tblActuals[Date],"<"&EDATE(H$3,1)) -> 0 | I8: =SUMIFS(tblActuals[Amount],tblActuals[P&L Category],$A8,tblActuals[Date],">="&I$3,tblActuals[Date],"<"&EDATE(I$3,1)) -> 0 | ... M8: =SUMIFS(tblActuals[Amount],tblActuals[P&L Category],$A8,tblActuals[Date],">="&M$3,tblActuals[Date],"<"&EDATE(M$3,1)) -> 0 | N8: =SUM(B8:M8) -> -742616.79
A9: Operating Profit | B9: =B6+B7+B8 -> 232297.8 | C9: =C6+C7+C8 -> 241053.35 | D9: =D6+D7+D8 -> 267061.07 | E9: =E6+E7+E8 -> 246235.66 | F9: =F6+F7+F8 -> 273359.46 | G9: =G6+G7+G8 -> 277332.65 | H9: =H6+H7+H8 -> 0 | I9: =I6+I7+I8 -> 0 | ... M9: =M6+M7+M8 -> 0 | N9: =SUM(B9:M9) -> 1537340
A11: Budget
A12: P&L Category | B12: =B3 -> 46023 | C12: =C3 -> 46054 | D12: =D3 -> 46082 | E12: =E3 -> 46113 | F12: =F3 -> 46143 | G12: =G3 -> 46174 | H12: =H3 -> 46204 | I12: =I3 -> 46235 | ... N12: =N3 -> YTD Jun
A13: Revenue | B13: =SUMIFS(Budget!$E:$E,Budget!$G:$G,$A13,Budget!$A:$A,">="&B$12,Budget!$A:$A,"<"&EDATE(B$12,1)) -> 894144.62 | C13: =SUMIFS(Budget!$E:$E,Budget!$G:$G,$A13,Budget!$A:$A,">="&C$12,Budget!$A:$A,"<"&EDATE(C$12,1)) -> 926290.92 | D13: =SUMIFS(Budget!$E:$E,Budget!$G:$G,$A13,Budget!$A:$A,">="&D$12,Budget!$A:$A,"<"&EDATE(D$12,1)) -> 932285.43 | E13: =SUMIFS(Budget!$E:$E,Budget!$G:$G,$A13,Budget!$A:$A,">="&E$12,Budget!$A:$A,"<"&EDATE(E$12,1)) -> 952517 | F13: =SUMIFS(Budget!$E:$E,Budget!$G:$G,$A13,Budget!$A:$A,">="&F$12,Budget!$A:$A,"<"&EDATE(F$12,1)) -> 958781.97 | G13: =SUMIFS(Budget!$E:$E,Budget!$G:$G,$A13,Budget!$A:$A,">="&G$12,Budget!$A:$A,"<"&EDATE(G$12,1)) -> 970304.16 | H13: =SUMIFS(Budget!$E:$E,Budget!$G:$G,$A13,Budget!$A:$A,">="&H$12,Budget!$A:$A,"<"&EDATE(H$12,1)) -> 997835.99 | I13: =SUMIFS(Budget!$E:$E,Budget!$G:$G,$A13,Budget!$A:$A,">="&I$12,Budget!$A:$A,"<"&EDATE(I$12,1)) -> 990437.11 | ... M13: =SUMIFS(Budget!$E:$E,Budget!$G:$G,$A13,Budget!$A:$A,">="&M$12,Budget!$A:$A,"<"&EDATE(M$12,1)) -> 1056049.7 | N13: =SUM(B13:G13) -> 5634324.1
A14: COGS | B14: =SUMIFS(Budget!$E:$E,Budget!$G:$G,$A14,Budget!$A:$A,">="&B$12,Budget!$A:$A,"<"&EDATE(B$12,1)) -> -352893.45 | C14: =SUMIFS(Budget!$E:$E,Budget!$G:$G,$A14,Budget!$A:$A,">="&C$12,Budget!$A:$A,"<"&EDATE(C$12,1)) -> -355379.89 | D14: =SUMIFS(Budget!$E:$E,Budget!$G:$G,$A14,Budget!$A:$A,">="&D$12,Budget!$A:$A,"<"&EDATE(D$12,1)) -> -359786.39 | E14: =SUMIFS(Budget!$E:$E,Budget!$G:$G,$A14,Budget!$A:$A,">="&E$12,Budget!$A:$A,"<"&EDATE(E$12,1)) -> -370643.92 | F14: =SUMIFS(Budget!$E:$E,Budget!$G:$G,$A14,Budget!$A:$A,">="&F$12,Budget!$A:$A,"<"&EDATE(F$12,1)) -> -367807.54 | G14: =SUMIFS(Budget!$E:$E,Budget!$G:$G,$A14,Budget!$A:$A,">="&G$12,Budget!$A:$A,"<"&EDATE(G$12,1)) -> -380698.08 | H14: =SUMIFS(Budget!$E:$E,Budget!$G:$G,$A14,Budget!$A:$A,">="&H$12,Budget!$A:$A,"<"&EDATE(H$12,1)) -> -383161.88 | I14: =SUMIFS(Budget!$E:$E,Budget!$G:$G,$A14,Budget!$A:$A,">="&I$12,Budget!$A:$A,"<"&EDATE(I$12,1)) -> -390897.36 | ... M14: =SUMIFS(Budget!$E:$E,Budget!$G:$G,$A14,Budget!$A:$A,">="&M$12,Budget!$A:$A,"<"&EDATE(M$12,1)) -> -405121.34 | N14: =SUM(B14:G14) -> -2187209.3
A15: Gross Profit | B15: =B13+B14 -> 541251.17 | C15: =C13+C14 -> 570911.03 | D15: =D13+D14 -> 572499.04 | E15: =E13+E14 -> 581873.08 | F15: =F13+F14 -> 590974.43 | G15: =G13+G14 -> 589606.08 | H15: =H13+H14 -> 614674.11 | I15: =I13+I14 -> 599539.75 | ... M15: =M13+M14 -> 650928.38 | N15: =SUM(B15:G15) -> 3447114.8
A16: Personnel | B16: =SUMIFS(Budget!$E:$E,Budget!$G:$G,$A16,Budget!$A:$A,">="&B$12,Budget!$A:$A,"<"&EDATE(B$12,1)) -> -201920.84 | C16: =SUMIFS(Budget!$E:$E,Budget!$G:$G,$A16,Budget!$A:$A,">="&C$12,Budget!$A:$A,"<"&EDATE(C$12,1)) -> -200544.89 | D16: =SUMIFS(Budget!$E:$E,Budget!$G:$G,$A16,Budget!$A:$A,">="&D$12,Budget!$A:$A,"<"&EDATE(D$12,1)) -> -207707.97 | E16: =SUMIFS(Budget!$E:$E,Budget!$G:$G,$A16,Budget!$A:$A,">="&E$12,Budget!$A:$A,"<"&EDATE(E$12,1)) -> -209147.22 | F16: =SUMIFS(Budget!$E:$E,Budget!$G:$G,$A16,Budget!$A:$A,">="&F$12,Budget!$A:$A,"<"&EDATE(F$12,1)) -> -213529.09 | G16: =SUMIFS(Budget!$E:$E,Budget!$G:$G,$A16,Budget!$A:$A,">="&G$12,Budget!$A:$A,"<"&EDATE(G$12,1)) -> -214853.73 | H16: =SUMIFS(Budget!$E:$E,Budget!$G:$G,$A16,Budget!$A:$A,">="&H$12,Budget!$A:$A,"<"&EDATE(H$12,1)) -> -217344.46 | I16: =SUMIFS(Budget!$E:$E,Budget!$G:$G,$A16,Budget!$A:$A,">="&I$12,Budget!$A:$A,"<"&EDATE(I$12,1)) -> -223666.17 | ... M16: =SUMIFS(Budget!$E:$E,Budget!$G:$G,$A16,Budget!$A:$A,">="&M$12,Budget!$A:$A,"<"&EDATE(M$12,1)) -> -235191.46 | N16: =SUM(B16:G16) -> -1247703.7
A17: Other OPEX | B17: =SUMIFS(Budget!$E:$E,Budget!$G:$G,$A17,Budget!$A:$A,">="&B$12,Budget!$A:$A,"<"&EDATE(B$12,1)) -> -114362.31 | C17: =SUMIFS(Budget!$E:$E,Budget!$G:$G,$A17,Budget!$A:$A,">="&C$12,Budget!$A:$A,"<"&EDATE(C$12,1)) -> -117043.73 | D17: =SUMIFS(Budget!$E:$E,Budget!$G:$G,$A17,Budget!$A:$A,">="&D$12,Budget!$A:$A,"<"&EDATE(D$12,1)) -> -117788.02 | E17: =SUMIFS(Budget!$E:$E,Budget!$G:$G,$A17,Budget!$A:$A,">="&E$12,Budget!$A:$A,"<"&EDATE(E$12,1)) -> -120033.73 | F17: =SUMIFS(Budget!$E:$E,Budget!$G:$G,$A17,Budget!$A:$A,">="&F$12,Budget!$A:$A,"<"&EDATE(F$12,1)) -> -121777.04 | G17: =SUMIFS(Budget!$E:$E,Budget!$G:$G,$A17,Budget!$A:$A,">="&G$12,Budget!$A:$A,"<"&EDATE(G$12,1)) -> -123171.48 | H17: =SUMIFS(Budget!$E:$E,Budget!$G:$G,$A17,Budget!$A:$A,">="&H$12,Budget!$A:$A,"<"&EDATE(H$12,1)) -> -125491.12 | I17: =SUMIFS(Budget!$E:$E,Budget!$G:$G,$A17,Budget!$A:$A,">="&I$12,Budget!$A:$A,"<"&EDATE(I$12,1)) -> -126678.27 | ... M17: =SUMIFS(Budget!$E:$E,Budget!$G:$G,$A17,Budget!$A:$A,">="&M$12,Budget!$A:$A,"<"&EDATE(M$12,1)) -> -134131.24 | N17: =SUM(B17:G17) -> -714176.31
A18: Operating Profit | B18: =B15+B16+B17 -> 224968.02 | C18: =C15+C16+C17 -> 253322.41 | D18: =D15+D16+D17 -> 247003.05 | E18: =E15+E16+E17 -> 252692.13 | F18: =F15+F16+F17 -> 255668.3 | G18: =G15+G16+G17 -> 251580.87 | H18: =H15+H16+H17 -> 271838.53 | I18: =I15+I16+I17 -> 249195.31 | ... M18: =M15+M16+M17 -> 281605.68 | N18: =SUM(B18:G18) -> 1485234.8
A20: Variance (€)
A21: P&L Category | B21: =B3 -> 46023 | C21: =C3 -> 46054 | D21: =D3 -> 46082 | E21: =E3 -> 46113 | F21: =F3 -> 46143 | G21: =G3 -> 46174 | H21: =H3 -> 46204 | I21: =I3 -> 46235 | ... N21: =N3 -> YTD Jun
A22: Revenue | B22: =B4-B13 -> 38501.38 | C22: =C4-C13 -> -122.31 | D22: =D4-D13 -> 61890.09 | E22: =E4-E13 -> 36087.76 | F22: =F4-F13 -> 91512.33 | G22: =G4-G13 -> 62108.88 | H22: =H4-H13 -> -997835.99 | I22: =I4-I13 -> -990437.11 | ... N22: =N4-N13 -> 289978.13
A23: COGS | B23: =B5-B14 -> -16217.55 | C23: =C5-C14 -> -9758.76 | D23: =D5-D14 -> -24379.21 | E23: =E5-E14 -> -20613.74 | F23: =F5-F14 -> -46267.22 | G23: =G5-G14 -> -18243.13 | H23: =H5-H14 -> 383161.88 | I23: =I5-I14 -> 390897.36 | ... N23: =N5-N14 -> -135479.61
A24: Gross Profit | B24: =B6-B15 -> 22283.83 | C24: =C6-C15 -> -9881.07 | D24: =D6-D15 -> 37510.88 | E24: =E6-E15 -> 15474.02 | F24: =F6-F15 -> 45245.11 | G24: =G6-G15 -> 43865.75 | H24: =H6-H15 -> -614674.11 | I24: =I6-I15 -> -599539.75 | ... N24: =N6-N15 -> 154498.52
A25: Personnel | B25: =B7-B16 -> -10085.56 | C25: =C7-C16 -> -3816.26 | D25: =D7-D16 -> -12464.19 | E25: =E7-E16 -> -15579.56 | F25: =F7-F16 -> -18220.67 | G25: =G7-G16 -> -13786.59 | H25: =H7-H16 -> 217344.46 | I25: =I7-I16 -> 223666.17 | ... N25: =N7-N16 -> -73952.83
A26: Other OPEX | B26: =B8-B17 -> -4868.49 | C26: =C8-C17 -> 1428.27 | D26: =D8-D17 -> -4988.67 | E26: =E8-E17 -> -6350.93 | F26: =F8-F17 -> -9333.28 | G26: =G8-G17 -> -4327.38 | H26: =H8-H17 -> 125491.12 | I26: =I8-I17 -> 126678.27 | ... N26: =N8-N17 -> -28440.48
A27: Operating Profit | B27: =B9-B18 -> 7329.78 | C27: =C9-C18 -> -12269.06 | D27: =D9-D18 -> 20058.02 | E27: =E9-E18 -> -6456.47 | F27: =F9-F18 -> 17691.16 | G27: =G9-G18 -> 25751.78 | H27: =H9-H18 -> -271838.53 | I27: =I9-I18 -> -249195.31 | ... N27: =N9-N18 -> 52105.21
A29: Variance (%)
A30: P&L Category | B30: =B3 -> 46023 | C30: =C3 -> 46054 | D30: =D3 -> 46082 | E30: =E3 -> 46113 | F30: =F3 -> 46143 | G30: =G3 -> 46174 | H30: =H3 -> 46204 | I30: =I3 -> 46235 | ... N30: =N3 -> YTD Jun
A31: Revenue | B31: =IF(B4=0,"",IFERROR((B4-B13)/ABS(B13),0)) -> 0.043059455 | C31: =IF(C4=0,"",IFERROR((C4-C13)/ABS(C13),0)) -> -0.00013204275 | D31: =IF(D4=0,"",IFERROR((D4-D13)/ABS(D13),0)) -> 0.066385345 | E31: =IF(E4=0,"",IFERROR((E4-E13)/ABS(E13),0)) -> 0.037886736 | F31: =IF(F4=0,"",IFERROR((F4-F13)/ABS(F13),0)) -> 0.095446444 | G31: =IF(G4=0,"",IFERROR((G4-G13)/ABS(G13),0)) -> 0.064009702 | H31: =IF(H4=0,"",IFERROR((H4-H13)/ABS(H13),0)) | I31: =IF(I4=0,"",IFERROR((I4-I13)/ABS(I13),0)) | ... M31: =IF(M4=0,"",IFERROR((M4-M13)/ABS(M13),0)) | N31: =IFERROR((N4-N13)/ABS(N13),0) -> 0.051466356
A32: COGS
A33: Gross Profit
A34: Personnel
A35: Other OPEX
A36: Operating Profit
A38: Forecast | P38: Forecast Assumptions | Q38: Value
A39: P&L Category | B39: =B3 -> 46023 | C39: =C3 -> 46054 | D39: =D3 -> 46082 | E39: =E3 -> 46113 | F39: =F3 -> 46143 | G39: =G3 -> 46174 | H39: =H3 -> 46204 | I39: =I3 -> 46235 | ... M39: =M3 -> 46357 | N39: FY 2026 | P39: Revenue vs Budget | Q39: 0.03
A40: Revenue | B40: =B4 -> 932646 | C40: =C4 -> 926168.61 | D40: =D4 -> 994175.52 | E40: =E4 -> 988604.76 | F40: =F4 -> 1050294.3 | G40: =G4 -> 1032413 | H40: =H13*(1+$Q$39) -> 1027771.1 | I40: =I13*(1+$Q$39) -> 1020150.2 | J40: =J13*(1+$Q$39) -> 1055269.9 | K40: =K13*(1+$Q$39) -> 1060579 | L40: =L13*(1+$Q$39) -> 1082087.3 | M40: =M13*(1+$Q$39) -> 1087731.2 | N40: =SUM(B40:M40) -> 12257891 | P40: COGS vs Budget | Q40: 0.02
A41: COGS | B41: =B5 -> -369111 | C41: =C5 -> -365138.65 | D41: =D5 -> -384165.6 | E41: =E5 -> -391257.66 | F41: =F5 -> -414074.76 | G41: =G5 -> -398941.21 | H41: =H14*(1+$Q$40) -> -390825.12 | I41: =I14*(1+$Q$40) -> -398715.31 | J41: =J14*(1+$Q$40) -> -400933.14 | K41: =K14*(1+$Q$40) -> -405323.53 | L41: =L14*(1+$Q$40) -> -416974.42 | M41: =M14*(1+$Q$40) -> -413223.77 | N41: =SUM(B41:M41) -> -4748684.2 | P41: Personnel vs Budget | Q41: 0
A42: Gross Profit | B42: =B40+B41 -> 563535 | C42: =C40+C41 -> 561029.96 | D42: =D40+D41 -> 610009.92 | E42: =E40+E41 -> 597347.1 | F42: =F40+F41 -> 636219.54 | G42: =G40+G41 -> 633471.83 | H42: =H40+H41 -> 636945.95 | I42: =I40+I41 -> 621434.92 | ... M42: =M40+M41 -> 674507.44 | N42: =SUM(B42:M42) -> 7509206.9 | P42: Other OPEX vs Budget | Q42: -0.02
A43: Personnel | B43: =B7 -> -212006.4 | C43: =C7 -> -204361.15 | D43: =D7 -> -220172.16 | E43: =E7 -> -224726.78 | F43: =F7 -> -231749.76 | G43: =G7 -> -228640.32 | H43: =H16*(1+$Q$41) -> -217344.46 | I43: =I16*(1+$Q$41) -> -223666.17 | J43: =J16*(1+$Q$41) -> -221814.81 | K43: =K16*(1+$Q$41) -> -229408.81 | L43: =L16*(1+$Q$41) -> -230677.1 | M43: =M16*(1+$Q$41) -> -235191.46 | N43: =SUM(B43:M43) -> -2679759.4
A44: Other OPEX | B44: =B8 -> -119230.8 | C44: =C8 -> -115615.46 | D44: =D8 -> -122776.69 | E44: =E8 -> -126384.66 | F44: =F8 -> -131110.32 | G44: =G8 -> -127498.86 | H44: =H17*(1+$Q$42) -> -122981.3 | I44: =I17*(1+$Q$42) -> -124144.7 | J44: =J17*(1+$Q$42) -> -126868.3 | K44: =K17*(1+$Q$42) -> -127492.36 | L44: =L17*(1+$Q$42) -> -129742.33 | M44: =M17*(1+$Q$42) -> -131448.62 | N44: =SUM(B44:M44) -> -1505294.4
A45: Operating Profit | B45: =B42+B43+B44 -> 232297.8 | C45: =C42+C43+C44 -> 241053.35 | D45: =D42+D43+D44 -> 267061.07 | E45: =E42+E43+E44 -> 246235.66 | F45: =F42+F43+F44 -> 273359.46 | G45: =G42+G43+G44 -> 277332.65 | H45: =H42+H43+H44 -> 296620.19 | I45: =I42+I43+I44 -> 273624.04 | ... M45: =M42+M43+M44 -> 307867.37 | N45: =SUM(B45:M45) -> 3324153.1 | P45: FY Forecast vs Budget
...

Sheet Dashboard
A1: Northstar Industrial — Management Dashboard
A2: YTD June 2026
A4: YTD Revenue | D4: YTD Operating Profit | G4: OP Margin | J4: Revenue vs Budget
A5: ='P&L'!N4 -> 5924302.2 | D5: ='P&L'!N9 -> 1537340 | G5: =IFERROR(D5/A5,0) -> 0.25949723 | J5: ='P&L'!N22 -> 289978.13
A8: Monthly Performance
A9: Month | B9: Actual | C9: Budget
A10: Jan | B10: ='P&L'!B4 -> 932646 | C10: ='P&L'!B13 -> 894144.62
A11: Feb | B11: ='P&L'!C4 -> 926168.61 | C11: ='P&L'!C13 -> 926290.92
A12: Mar | B12: ='P&L'!D4 -> 994175.52 | C12: ='P&L'!D13 -> 932285.43
A13: Apr | B13: ='P&L'!E4 -> 988604.76 | C13: ='P&L'!E13 -> 952517
A14: May | B14: ='P&L'!F4 -> 1050294.3 | C14: ='P&L'!F13 -> 958781.97
A15: Jun | B15: ='P&L'!G4 -> 1032413 | C15: ='P&L'!G13 -> 970304.16
A20: Business Unit Performance
A21: Business Unit | B21: Revenue | C21: Operating Profit | D21: OP Margin | F21: Business Unit | G21: Operating Profit
A22: Automation Solutions | B22: ='P&L'!B51 -> 2455398.5 | C22: ='P&L'!G51 -> 624704.05 | D22: ='P&L'!H51 -> 0.25442064 | F22: Automation Solutions | G22: =C22 -> 624704.05
A23: Industrial Components | B23: ='P&L'!B52 -> 2039860.3 | C23: ='P&L'!G52 -> 546074.18 | D23: ='P&L'!H52 -> 0.26770176 | F23: Industrial Components | G23: =C23 -> 546074.18
A24: Service & Aftermarket | B24: ='P&L'!B53 -> 1429043.4 | C24: ='P&L'!G53 -> 366561.76 | D24: ='P&L'!H53 -> 0.25650848 | F24: Service & Aftermarket | G24: =C24 -> 366561.76
A30: Key Insights
A31: YTD revenue €5.92m, €290k above budget.
A32: YTD operating profit €1.54m with a 25.9% margin.
A33: Industrial Components has the highest OP margin at 26.8%.
A34: Automation Solutions generates the highest absolute operating profit at €625k.

Sheet Actuals
A1: Date | B1: Account | C1: Cost Center | D1: Business Unit | E1: Amount | F1: Account Name | G1: P&L Category
A2: 46053 | B2: 3000 | C2: CC100 | D2: Automation Solutions | E2: 297600 | F2: =_xlfn.XLOOKUP(B2,Mapping!A:A,Mapping!B:B) -> Product Sales | G2: =_xlfn.XLOOKUP(B2,Mapping!A:A,Mapping!C:C) -> Revenue
A3: 46053 | B3: 3100 | C3: CC100 | D3: Automation Solutions | E3: 83300 | F3: =_xlfn.XLOOKUP(B3,Mapping!A:A,Mapping!B:B) -> Service Revenue | G3: =_xlfn.XLOOKUP(B3,Mapping!A:A,Mapping!C:C) -> Revenue
A4: 46053 | B4: 4000 | C4: CC100 | D4: Automation Solutions | E4: -128000 | F4: =_xlfn.XLOOKUP(B4,Mapping!A:A,Mapping!B:B) -> Materials | G4: =_xlfn.XLOOKUP(B4,Mapping!A:A,Mapping!C:C) -> COGS
A5: 46053 | B5: 4100 | C5: CC100 | D5: Automation Solutions | E5: -27540 | F5: =_xlfn.XLOOKUP(B5,Mapping!A:A,Mapping!B:B) -> Freight & Logistics | G5: =_xlfn.XLOOKUP(B5,Mapping!A:A,Mapping!C:C) -> COGS
A6: 46053 | B6: 5000 | C6: CC100 | D6: Automation Solutions | E6: -74880 | F6: =_xlfn.XLOOKUP(B6,Mapping!A:A,Mapping!B:B) -> Salaries | G6: =_xlfn.XLOOKUP(B6,Mapping!A:A,Mapping!C:C) -> Personnel
A7: 46053 | B7: 5100 | C7: CC100 | D7: Automation Solutions | E7: -15520 | F7: =_xlfn.XLOOKUP(B7,Mapping!A:A,Mapping!B:B) -> Employee Benefits | G7: =_xlfn.XLOOKUP(B7,Mapping!A:A,Mapping!C:C) -> Personnel
A8: 46053 | B8: 6000 | C8: CC100 | D8: Automation Solutions | E8: -14850 | F8: =_xlfn.XLOOKUP(B8,Mapping!A:A,Mapping!B:B) -> Rent | G8: =_xlfn.XLOOKUP(B8,Mapping!A:A,Mapping!C:C) -> Other OPEX
A9: 46053 | B9: 6100 | C9: CC100 | D9: Automation Solutions | E9: -12120 | F9: =_xlfn.XLOOKUP(B9,Mapping!A:A,Mapping!B:B) -> IT & Software | G9: =_xlfn.XLOOKUP(B9,Mapping!A:A,Mapping!C:C) -> Other OPEX
A10: 46053 | B10: 6200 | C10: CC100 | D10: Automation Solutions | E10: -9270 | F10: =_xlfn.XLOOKUP(B10,Mapping!A:A,Mapping!B:B) -> Marketing | G10: =_xlfn.XLOOKUP(B10,Mapping!A:A,Mapping!C:C) -> Other OPEX
A11: 46053 | B11: 6300 | C11: CC100 | D11: Automation Solutions | E11: -5280 | F11: =_xlfn.XLOOKUP(B11,Mapping!A:A,Mapping!B:B) -> Travel | G11: =_xlfn.XLOOKUP(B11,Mapping!A:A,Mapping!C:C) -> Other OPEX
A12: 46053 | B12: 6400 | C12: CC100 | D12: Automation Solutions | E12: -7840 | F12: =_xlfn.XLOOKUP(B12,Mapping!A:A,Mapping!B:B) -> Professional Services | G12: =_xlfn.XLOOKUP(B12,Mapping!A:A,Mapping!C:C) -> Other OPEX
A13: 46053 | B13: 3000 | C13: CC200 | D13: Industrial Components | E13: 256742 | F13: =_xlfn.XLOOKUP(B13,Mapping!A:A,Mapping!B:B) -> Product Sales | G13: =_xlfn.XLOOKUP(B13,Mapping!A:A,Mapping!C:C) -> Revenue
... A199: 46203 | B199: 6400 | C199: CC300 | D199: Service & Aftermarket | E199: -4810.75 | F199: =_xlfn.XLOOKUP(B199,Mapping!A:A,Mapping!B:B) -> Professional Services | G199: =_xlfn.XLOOKUP(B199,Mapping!A:A,Mapping!C:C) -> Other OPEX

Sheet Budget
A1: Date | B1: Account | C1: Cost Center | D1: Business Unit | E1: Budget Amount | F1: Account Name | G1: P&L Category
A2: 46053 | B2: 3000 | C2: CC100 | D2: Automation Solutions | E2: 288453.75 | F2: =_xlfn.XLOOKUP(B2,Mapping!A:A,Mapping!B:B) -> Product Sales | G2: =_xlfn.XLOOKUP(B2,Mapping!A:A,Mapping!C:C) -> Revenue
A3: 46053 | B3: 3100 | C3: CC100 | D3: Automation Solutions | E3: 79950 | F3: =_xlfn.XLOOKUP(B3,Mapping!A:A,Mapping!B:B) -> Service Revenue | G3: =_xlfn.XLOOKUP(B3,Mapping!A:A,Mapping!C:C) -> Revenue | I3: =LEN(Budget!G2) -> 7
A4: 46053 | B4: 4000 | C4: CC100 | D4: Automation Solutions | E4: -124527 | F4: =_xlfn.XLOOKUP(B4,Mapping!A:A,Mapping!B:B) -> Materials | G4: =_xlfn.XLOOKUP(B4,Mapping!A:A,Mapping!C:C) -> COGS
A5: 46053 | B5: 4100 | C5: CC100 | D5: Automation Solutions | E5: -25096.5 | F5: =_xlfn.XLOOKUP(B5,Mapping!A:A,Mapping!B:B) -> Freight & Logistics | G5: =_xlfn.XLOOKUP(B5,Mapping!A:A,Mapping!C:C) -> COGS
A6: 46053 | B6: 5000 | C6: CC100 | D6: Automation Solutions | E6: -69615 | F6: =_xlfn.XLOOKUP(B6,Mapping!A:A,Mapping!B:B) -> Salaries | G6: =_xlfn.XLOOKUP(B6,Mapping!A:A,Mapping!C:C) -> Personnel
A7: 46053 | B7: 5100 | C7: CC100 | D7: Automation Solutions | E7: -14810.25 | F7: =_xlfn.XLOOKUP(B7,Mapping!A:A,Mapping!B:B) -> Employee Benefits | G7: =_xlfn.XLOOKUP(B7,Mapping!A:A,Mapping!C:C) -> Personnel
A8: 46053 | B8: 6000 | C8: CC100 | D8: Automation Solutions | E8: -14771.25 | F8: =_xlfn.XLOOKUP(B8,Mapping!A:A,Mapping!B:B) -> Rent | G8: =_xlfn.XLOOKUP(B8,Mapping!A:A,Mapping!C:C) -> Other OPEX
A9: 46053 | B9: 6100 | C9: CC100 | D9: Automation Solutions | E9: -10876.12 | F9: =_xlfn.XLOOKUP(B9,Mapping!A:A,Mapping!B:B) -> IT & Software | G9: =_xlfn.XLOOKUP(B9,Mapping!A:A,Mapping!C:C) -> Other OPEX
A10: 46053 | B10: 6200 | C10: CC100 | D10: Automation Solutions | E10: -9262.5 | F10: =_xlfn.XLOOKUP(B10,Mapping!A:A,Mapping!B:B) -> Marketing | G10: =_xlfn.XLOOKUP(B10,Mapping!A:A,Mapping!C:C) -> Other OPEX
A11: 46053 | B11: 6300 | C11: CC100 | D11: Automation Solutions | E11: -5222.1 | F11: =_xlfn.XLOOKUP(B11,Mapping!A:A,Mapping!B:B) -> Travel | G11: =_xlfn.XLOOKUP(B11,Mapping!A:A,Mapping!C:C) -> Other OPEX
A12: 46053 | B12: 6400 | C12: CC100 | D12: Automation Solutions | E12: -7528.95 | F12: =_xlfn.XLOOKUP(B12,Mapping!A:A,Mapping!B:B) -> Professional Services | G12: =_xlfn.XLOOKUP(B12,Mapping!A:A,Mapping!C:C) -> Other OPEX
A13: 46053 | B13: 3000 | C13: CC200 | D13: Industrial Components | E13: 246285.98 | F13: =_xlfn.XLOOKUP(B13,Mapping!A:A,Mapping!B:B) -> Product Sales | G13: =_xlfn.XLOOKUP(B13,Mapping!A:A,Mapping!C:C) -> Revenue
A14: 46053 | B14: 3100 | C14: CC200 | D14: Industrial Components | E14: 63592.23 | F14: =_xlfn.XLOOKUP(B14,Mapping!A:A,Mapping!B:B) -> Service Revenue | G14: =_xlfn.XLOOKUP(B14,Mapping!A:A,Mapping!C:C) -> Revenue
A15: 46053 | B15: 4000 | C15: CC200 | D15: Industrial Components | E15: -99138 | F15: =_xlfn.XLOOKUP(B15,Mapping!A:A,Mapping!B:B) -> Materials | G15: =_xlfn.XLOOKUP(B15,Mapping!A:A,Mapping!C:C) -> COGS
... A397: 46387 | B397: 6400 | C397: CC300 | D397: Service & Aftermarket | E397: -5208.93 | F397: =_xlfn.XLOOKUP(B397,Mapping!A:A,Mapping!B:B) -> Professional Services | G397: =_xlfn.XLOOKUP(B397,Mapping!A:A,Mapping!C:C) -> Other OPEX

Sheet Forecast Assumptions
A1: Forecast Assumptions — FY2026
A2: Assumption | B2: Value
A3: Revenue vs Budget | B3: 0.03
A4: COGS vs Budget | B4: 0.02
A5: Personnel vs Budget | B5: 0
A6: Other OPEX vs Budget | B6: -0.02
A9: Forecast Methodology
A10: Jan–Jun forecast is based on actual results. Jul–Dec forecast is based on monthly budget adjusted by the assumptions above.
A12: Forecast Output
A14: FY2026 Revenue Forecast | B14: ='P&L'!N40 -> 12257891
A15: FY2026 Operating Profit Forecast | B15: ='P&L'!N45 -> 3324153.1
A16: Revenue vs FY Budget | B16: ='P&L'!N40-SUM('P&L'!B13:M13) -> 474451.59
A17: Operating Profit vs FY Budget | B17: ='P&L'!N45-SUM('P&L'!B18:M18) -> 204574.98

Sheet Mapping
A1: Sarake1 | B1: Account Name | C1: P&L Category
A2: 3000 | B2: Product Sales | C2: Revenue
A3: 3100 | B3: Service Revenue | C3: Revenue
A4: 4000 | B4: Materials | C4: COGS
A5: 4100 | B5: Freight & Logistics | C5: COGS
A6: 5000 | B6: Salaries | C6: Personnel
A7: 5100 | B7: Employee Benefits | C7: Personnel
A8: 6000 | B8: Rent | C8: Other OPEX
A9: 6100 | B9: IT & Software | C9: Other OPEX
A10: 6200 | B10: Marketing | C10: Other OPEX
A11: 6300 | B11: Travel | C11: Other OPEX
A12: 6400 | B12: Professional Services | C12: Other OPEX
